Workbook

Sheet cronograma Actividades
B2: Tener sesion con Fabricantes sobre dudas el RFP
B3: Actualizar RFP con observaciones identificadas
B4: Tener sesion con empresas y fabricantes, agrupados por Fabricante
B5: Validar Volumetria y capacidades con fabricante
B6: Definir fechas de Demostracion con empresas participantes

Sheet 01-alcance
A1: N° | B1: Empresa | C1: País | D1: Fecha Contrato | E1: WAF AS-IS | F1: Tipo Contrato | G1: Partner | H1: Operación
A2: 1 | B2: Mi Banco Peru | C2: Perú | D2: 46357 | E2: Cloudflare | F2: Licencia | G2: Nek–SecureSoft | H2: Autogestionado
A3: 2 | B3: Mi Banco - Colombia | C3: Colombia | D3: 46082 | E3: Imperva | F3: Contrato | G3: SecureSoft | H3: Autogestionado
A4: 3 | B4: Tenpo | C4: Chile | D4: 46023 | E4: Cloudflare | F4: PAYG | G4: No aplica | H4: Autogestionado
A5: 4 | B5: Pacifico-Prestadoras de Salud | C5: Perú | D5: 46569 | E5: Akamai | F5: Contrato | G5: Apukay | H5: Tercerizado
A6: 5 | B6: Credicorp Capital Colombia | C6: Colombia | D6: 46569 | E6: Cloudflare | F6: Contrato | G6: Linxsource | H6: Autogestionado
B7: Credicorp Capital Chile | C7: Chile
B8: ASB - Panamá | C8: Panamá
B9: Credicorp Capital Peru | C9: Perú
B10: Credicorp Capital USA | C10: USA
A11: 6 | B11: Pacifico Salud/EPS | C11: Perú | D11: 46600 | E11: Akamai | F11: Contrato | G11: Apukay | H11: Tercerizado
A12: 7 | B12: YAPE – Perú | C12: Perú | D12: 46600 | E12: Imperva | F12: Contrato | G12: SecureSoft | H12: Autogestionado
A13: 8 | B13: YAPE – Bolivia | C13: Bolivia | D13: 46631 | E13: Radware | F13: Nuevo | G13: Cloud Factory | H13: Tercerizado
A14: 9 | B14: BCB Bolivia | C14: Bolivia | D14: 46631 | E14: Radware | F14: Contrato | G14: Cloud Factory | H14: Tercerizado
A15: 10 | B15: IO | C15: Perú | D15: No Aplica | E15: AWS FW | F15: PAYG | G15: No aplica | H15: Autogestionado
A16: 11 | B16: Pacifico Seguros | C16: Perú | D16: No Aplica | E16: Frontdoor | F16: PAYG | G16: No aplica | H16: Autogestionado
A17: 12 | B17: Prima AFP | C17: Perú | D17: No Aplica | E17: Frontdoor | F17: PAYG | G17: No aplica | H17: Autogestionado
A18: 13 | B18: Culqui | C18: Perú | D18: No Aplica | E18: AWS FW | F18: PAYG | G18: No aplica | H18: Autogestionado
A19: 14 | B19: BCP Miami | C19: USA | D19: No Aplica | E19: Frontdoor | F19: PAYG | G19: No aplica | H19: Autogestionado
A20: 15 | B20: Monokera | C20: Colombia | D20: No Aplica | E20: AWS FW | F20: PAYG | G20: No aplica | H20: Autogestionado
A21: 16 | B21: Tyba | C21: Perú | D21: No Aplica | E21: AWS FW | F21: PAYG | G21: No aplica | H21: Autogestionado

Sheet 01-CISOs
A1: N° | B1: Empresa | C1: País | D1: Fecha Contrato | E1: WAF AS-IS | F1: CISO | G1: email | H1: Tipo Contrato | I1: Partner | J1: Operación
A2: 1 | B2: Mi Banco Peru | C2: Perú | D2: 46357 | E2: Cloudflare | F2: Pedro Fernández | G2: pedro.fernandez.c@mibanco.com.pe | H2: Licencia | I2: Nek–SecureSoft | J2: Autogestionado
A3: 2 | B3: Mi Banco - Colombia | C3: Colombia | D3: 46082 | E3: Imperva | F3: Viviana Mora | G3: viviana.moral@mibanco.com.co | H3: Contrato | I3: SecureSoft | J3: Autogestionado
A4: 3 | B4: Tenpo | C4: Chile | D4: 46023 | E4: Cloudflare | F4: Sebastian Véliz | G4: sebastian.veliz@tenpo.cl | H4: PAYG | I4: No aplica | J4: Autogestionado
A5: 4 | B5: Pacifico-Prestadoras de Salud | C5: Perú | D5: 46569 | E5: Akamai | F5: Juan Luis Morales | G5: juanluismorales@pacifico.com.pe | H5: Contrato | I5: Apukay | J5: Tercerizado
A6: 5 | B6: Credicorp Capital Colombia | C6: Colombia | D6: 46569 | E6: Cloudflare | F6: Paula Vaca; Jorge Pineda | G6: pvaca@credicorpcapital.com ; jorgepinedah@credicorpcapital.com | H6: Contrato | I6: Linxsource | J6: Autogestionado
B7: Credicorp Capital Chile | C7: Chile
B8: ASB - Panamá | C8: Panamá
B9: Credicorp Capital Peru | C9: Perú
B10: Credicorp Capital USA | C10: USA
A11: 6 | B11: Pacifico Salud/EPS | C11: Perú | D11: 46600 | E11: Akamai | F11: Juan Luis Morales | G11: juanluismorales@pacifico.com.pe | H11: Contrato | I11: Apukay | J11: Tercerizado
A12: 7 | B12: YAPE – Perú | C12: Perú | D12: 46600 | E12: Imperva | F12: Camilo Navas | G12: camilonavas@yape.com.pe | H12: Contrato | I12: SecureSoft | J12: Autogestionado
A13: 8 | B13: YAPE – Bolivia | C13: Bolivia | D13: 46631 | E13: Radware | F13: Camilo Navas | G13: camilonavas@yape.com.pe | H13: Nuevo | I13: Cloud Factory | J13: Tercerizado
A14: 9 | B14: BCB Bolivia | C14: Bolivia | D14: 46631 | E14: Radware | F14: Luxen Gumucio | G14: jgumucio@bcp.com.bo | H14: Contrato | I14: Cloud Factory | J14: Tercerizado
A15: 10 | B15: IO | C15: Perú | D15: No Aplica | E15: AWS FW | F15: Camilo Navas | G15: camilonavas@yape.com.pe | H15: PAYG | I15: No aplica | J15: Autogestionado
A16: 11 | B16: Pacifico Seguros | C16: Perú | D16: No Aplica | E16: Frontdoor | F16: Joan Cáceres | G16: jocaceres@pacifico.com.pe | H16: PAYG | I16: No aplica | J16: Autogestionado
A17: 12 | B17: Prima AFP | C17: Perú | D17: No Aplica | E17: Frontdoor | F17: Kassandra Georgina Jaramillo Calvo | G17: kassandrajaramillo@prima.com.pe | H17: PAYG | I17: No aplica | J17: Autogestionado
A18: 13 | B18: Culqui | C18: Perú | D18: No Aplica | E18: AWS FW | F18: Jesus Napuri | G18: jesus.napuri@culqi.com | H18: PAYG | I18: No aplica | J18: Autogestionado
A19: 14 | B19: BCP Miami | C19: USA | D19: No Aplica | E19: Frontdoor | F19: Jose Palomino | G19: jpalomino@bcpmiami.com | H19: PAYG | I19: No aplica | J19: Autogestionado
A20: 15 | B20: Monokera | C20: Colombia | D20: No Aplica | E20: AWS FW | F20: Kelly Correa | G20: kelly.correa@monokera.com | H20: PAYG | I20: No aplica | J20: Autogestionado
A21: 16 | B21: Tyba | C21: Perú | D21: No Aplica | E21: AWS FW | F21: Julian Sanchez | G21: juliansanchez@tyba.com.co | H21: PAYG | I21: No aplica | J21: Autogestionado

Sheet 01-Contactos Especialistas
A1: N° | B1: Empresa | C1: País | D1: Fecha Contrato | E1: WAF AS-IS | F1: CISO | G1: email | H1: Confirmo | I1: Especialistas de la empresa | J1: email | K1: participacion en calificacion | L1: Tipo Contrato | M1: Partner | N1: Operación
A2: 4 | B2: Pacifico Prestaciones / Laboratorios | C2: Perú | D2: 46569 | E2: Akamai | F2: Juan Luis Morales | G2: juanluismorales@pacifico.com.pe | H2: SI | I2: Stefano Ivan Arrieta Escalaya; Miguel Valeriano; Alexis Bautista | J2: StefanoArrietaE@pacifico.com.pe; miguel.valeriano@aliada.com.pe; abautista@clinicasanfelipe.com | L2: Contrato | M2: Apukay | N2: Tercerizado
A3: 6 | B3: PACIFICO SALUD | C3: Perú | D3: 46600 | E3: Akamai | F3: Juan Luis Morales | G3: juanluismorales@pacifico.com.pe | H3: SI | I3: Stefano Ivan Arrieta Escalaya; Wilian Fabian ; Miguel Valeriano | J3: StefanoArrietaE@pacifico.com.pe; WilianFabianE@pacifico.com.pe; miguel.valeriano@aliada.com.pe | L3: Contrato | M3: Apukay | N3: Tercerizado
A4: 10 | B4: iO | C4: Perú | D4: No Aplica | E4: AWS FW | H4: SI | I4: Fredy Gerardo Mendez Gonzales; Rodrigo Diaz Romero | J4: fredymendez@bcp.com.pe; rodrigoadiaz@bcp.com.pe | L4: PAYG | M4: No aplica | N4: Autogestionado
A5: 13 | B5: Culqui | C5: Perú | D5: No Aplica | E5: AWS FW | F5: Jesus Napuri | G5: jesus.napuri@culqi.com | H5: SI | I5: Freddy Javier Meres Vargas | J5: freddymeres@bcp.com.pe | L5: PAYG | M5: No aplica | N5: Autogestionado
A6: 15 | B6: Monokera | C6: Colombia | D6: No Aplica | E6: AWS FW | F6: Kelly Correa | G6: kelly.correa@monokera.com | H6: SI | I6: Edison Mayo | J6: edison.mayo@monokera.com | L6: PAYG | M6: No aplica | N6: Autogestionado
A7: 16 | B7: Tyba | C7: Perú | D7: No Aplica | E7: AWS FW | F7: Julian Sanchez | G7: juliansanchez@tyba.com.co | H7: SI | I7: Victoria Alexandra Perez Cerveleon ; Stiben Pérez ; | J7: stiben@tyba.com.co ; victoriaperez@tyba.com.co; | L7: PAYG | M7: No aplica | N7: Autogestionado
A8: 1 | B8: Mi Banco Perú | C8: Perú | D8: 46357 | E8: Cloudflare | F8: Pedro Fernández | G8: pedro.fernandez.c@mibanco.com.pe | H8: SI | I8: Angelo Avalos; Giancarlo Andre Palacios Loayza | J8: angelo.avalos.pa@mibanco.com.pe; giancarlo.palacios.l@mibanco.com.pe | K8: SI | L8: Licencia | M8: Nek–SecureSoft | N8: Autogestionado
A9: 3 | B9: Tenpo | C9: Chile | D9: 46023 | E9: Cloudflare | F9: Sebastian Véliz | G9: sebastian.veliz@tenpo.cl | H9: SI | I9: Francisco Carreño: Art Gonzales: | J9: francisco.carreno@tenpo.cl; art.gonzales@tenpo.cl | K9: SI | L9: PAYG | M9: No aplica | N9: Autogestionado
A10: 5 | B10: CREDICORP CAPITAL | C10: Multi país | D10: 46569 | E10: Cloudflare | F10: Paula Vaca | G10: pvaca@credicorpcapital.com | H10: SI | I10: Sherly Acosta; Roberto Barcenas; Victor Hugo Vargas (frontdoor); Erwin espitia; Guillermo Steven Lluen (cloudflare) | J10: sacosta@asbnet.com.pa; rbarcenas@asbnet.com.pa; vvargas@credicorpcapital.com; eespitia@credicorpcapital.com; guillermolluen@credicorpcapital.com | L10: Contrato | M10: Linxsource | N10: Autogestionado
A11: 11 | B11: Pacifico Seguros y Pensiones | C11: Perú | D11: No Aplica | E11: Frontdoor | F11: Joan Cáceres | G11: jocaceres@pacifico.com.pe | H11: SI | I11: Felipe Soto; Miguel Villanueva | J11: luissoto@prima.com.pe; miguelvillanuevaa@pacifico.com.pe | K11: SI | L11: PAYG | M11: No aplica | N11: Autogestionado
A12: 12 | B12: Prima AFP | C12: Perú | D12: No Aplica | E12: Frontdoor | F12: Kassandra Georgina Jaramillo Calvo | G12: kassandrajaramillo@prima.com.pe | H12: SI | I12: Felipe Soto; Miguel Villanueva | J12: luissoto@prima.com.pe; miguelvillanuevaa@pacifico.com.pe | K12: SI | L12: PAYG | M12: No aplica | N12: Autogestionado
A13: 14 | B13: Banco de Crédito de Miami | C13: USA | D13: No Aplica | E13: Frontdoor | F13: Jose Palomino | G13: jpalomino@bcpmiami.com | H13: SI | I13: Li Chuica | J13: lchuica@bcpmiami.com | L13: PAYG | M13: No aplica | N13: Autogestionado
A14: 2 | B14: Mi Banco Colombia | C14: Colombia | D14: 46082 | E14: Imperva | F14: Viviana Mora | G14: viviana.moral@mibanco.com.co | H14: SI | I14: Angelo Avalos | J14: angelo.avalos.pa@mibanco.com.pe | K14: SI | L14: Contrato | M14: SecureSoft | N14: Autogestionado
A15: 7 | B15: Yape Perú | C15: Perú | D15: 46600 | E15: Imperva | F15: Camilo Navas | G15: camilonavas@yape.com.pe | H15: SI | I15: Fredy Gerardo Mendez Gonzales | J15: fredymendez@bcp.com.pe | K15: SI | L15: Contrato | M15: SecureSoft | N15: Autogestionado
A16: 8 | B16: Yape Bolivia | C16: Bolivia | D16: 46631 | E16: Radware | F16: Camilo Navas | G16: camilonavas@yape.com.pe | H16: SI | I16: Cesar Rollano; Fredy Gerardo Mendez Gonzales; Rodrigo Diaz Romero | J16: cirollanol@bcp.com.bo; fredymendez@bcp.com.pe; rodrigoadiaz@bcp.com.pe | K16: SI | L16: Nuevo | M16: Cloud Factory | N16: Tercerizado
A17: 9 | B17: Banco de Crédito de Bolivia | C17: Bolivia | D17: 46631 | E17: Radware | F17: Luxen Gumucio | G17: jgumucio@bcp.com.bo | H17: SI | I17: Cesar Rollano | J17: cirollanol@bcp.com.bo | K17: SI | L17: Contrato | M17: Cloud Factory | N17: Tercerizado

Sheet 01-Contacto Partners
A1: WAF
A2: Marca | B2: TipoContacto | C2: Nombre Empresa | D2: ROL | E2: Contacto | F2: email | G2: telefono
A3: CLOUDFLARE | B3: FABRICANTE | C3: CLOUDFLARE | D3: Cuenta LATAM | E3: Sebastian Romero | F3: sromeroortega@cloudflare.com | G3: +1(512)761-1312
A4: IMPERVA | B4: FABRICANTE | C4: IMPERVA | D4: Gerente WAF | E4: Lina Bermudez | F4: lina.bermudez@thalesgroup.com> | G4: +57(301)702-2462
A5: IMPERVA | B5: FABRICANTE | C5: IMPERVA | D5: Gerente de Cuenta | E5: Jair Melo | F5: jairo.melo@thalesgroup.com | G5: +57( 315)898-6104
A6: IMPERVA | B6: FABRICANTE | C6: IMPERVA | D6: gerente waf | E6: NicolasGomez | F6: nicolas-i.gomez@thalesgroup.com | G6: +57(310)558-6056
A7: IMPERVA | B7: FABRICANTE | C7: IMPERVA | D7: gerente latam | E7: Rodrigo Gutter
A8: IMPERVA | B8: FABRICANTE | C8: IMPERVA | D8: tecnico | E8: Baltazar QUIROZ | F8: balta.quiroz@thalesgroup.com | G8: +(52)552122-1405
A9: Radware | B9: FABRICANTE | C9: Radware | D9: Comercial Latam | E9: Piero Jose Garmendia Ramirez | F9: PieroG@radware.com | G9: +(51) 990449400
A10: Radware | B10: FABRICANTE | C10: Radware | D10: Tecnico | E10: Ivan Delgadillo | F10: Ivan.Delgadillo@radware.com | G10: +(51) 980411757
A11: Cloudfare | B11: PARTNER | C11: IBM | D11: Cuenta BCP | E11: IBM: Wendy Segovia | F11: wendys@pe.ibm.com
A12: Cloudfare | B12: PARTNER | C12: SecureSoft | D12: TAM | E12: Pamela Bozano | F12: pbozano@securesoftcorp.com
A13: IMPERVA | B13: PARTNER | C13: ASPER | D13: Comercial | E13: Thiago Goncalves | F13: thiago.goncalves@asper.tec.br | G13: +(55)1194159-1467
A14: IMPERVA | B14: PARTNER | C14: ASPER | D14: Comercial | E14: Gabriel Lira Barra | F14: gabriel.barra@asper.tec.br | G14: +1(26)621 337-67
A15: Radware | B15: PARTNER | C15: Italtel | D15: Gerente Italtel | E15: Italtel: Moises Perez | F15: moises.perez@italtel.com | G15: +(51)943270217
A16: Radware | B16: PARTNER | C16: INDRA | D16: Comercial | E16: Francisco Valdes | F16: fvaldes@indracompany.com
A17: Radware | B17: PARTNER | C17: Italtel | D17: Comercial | E17: Bryan Terrones | F17: bryan.terrones@italtel.com

Sheet 02-fechaContratos
O2: Fecha de Venc. Contractual
I3: FECHA VENCIMIENTO | O3: 46387 | S3: 46388 | V3: 46447 | X3: 46599 | AA3: 46608 | AD3: 46659 | AG3: PAYG | AN3: FECHA VENCIMIENTO | AQ3: Fecha de Venc. Contractual
H4: N° | I4: Seq° | J4: SUBSIDIARIA | K4: Producto Actual | L4: Throughput (GB) / Mes | M4: Cant. App FQDN (urls) | N4: Request WAF (M) / Mes | O4: Thgput (GB) / Acum | P4: cant. Apps | Q4: Req. WAF (M) / Acum | R4: Thgput (GB) / Acum | S4: cant. Apps | T4: Req. WAF (M) / Acum | U4: Thgput (GB) / Acum | V4: cant. Apps | W4: Req. WAF (M) / Acum | X4: Thgput (GB) / Acum | Y4: cant. Apps | Z4: Req. WAF (M) / Acum | AA4: Thgput (GB) / Acum | AB4: cant. Apps | AC4: Req. WAF (M) / Acum | AD4: Thgput (GB) / Acum | AE4: cant. Apps | AF4: Req. WAF (M) / Acum | AG4: Thgput (GB) / Acum | AH4: cant. Apps | AI4: Req. WAF (M) / Acum | AM4: N° | AN4: Seq° | AO4: SUBSIDIARIA | AP4: Producto Actual | AQ4: 46387 | AR4: 46388 | AS4: 46447 | AT4: 46599 | AU4: 46608 | AV4: 46659 | AW4: PAYG
H5: 1 | I5: 1 | J5: Mi Banco Peru | K5: Cloudfare | L5: ='03-VolumetriaCredActualizada'!G7 -> 0.0029 GBPS | M5: ='03-VolumetriaCredActualizada'!K7 -> 11 | N5: ='03-VolumetriaCredActualizada'!O7 -> 120 | O5: x | P5: x | Q5: x | AM5: 1 | AN5: 1 | AO5: Mi Banco Peru | AP5: Cloudfare | AQ5: x
H6: 13 | I6: 2 | J6: Tenpo - Chile | K6: Cloudfare | L6: ='03-VolumetriaCredActualizada'!G9 -> 0.00187 | M6: ='03-VolumetriaCredActualizada'!K9 -> 47 | N6: ='03-VolumetriaCredActualizada'!O9 -> 1250 | R6: x | S6: x | T6: x | AM6: 13 | AN6: 2 | AO6: Tenpo - Chile | AP6: Cloudfare | AR6: x
H7: 12 | I7: 3 | J7: Mi Banco - Colombia | K7: Imperva | L7: ='03-VolumetriaCredActualizada'!G4 -> 0.005 | M7: ='03-VolumetriaCredActualizada'!K4 -> 6 | N7: ='03-VolumetriaCredActualizada'!O4 -> 10.51421 | U7: x | V7: x | W7: x | AM7: 12 | AN7: 3 | AO7: Mi Banco - Colombia | AP7: Imperva | AS7: x
H8: 16 | I8: 5 | J8: Credicorp Capital Colombia | K8: Cloudfare/ Azure Frootdoor | L8: ='03-VolumetriaCredActualizada'!G10 -> 0.012 | M8: ='03-VolumetriaCredActualizada'!K10 -> 107 | N8: ='03-VolumetriaCredActualizada'!O10 -> 20.07 | X8: x | Y8: x | Z8: x | AM8: 16 | AN8: 4 | AO8: Credicorp Capital Colombia | AP8: Cloudfare/ Azure Frootdoor | AT8: x
H9: 16 | I9: 5 | J9: Credicorp Capital Chile | AM9: 16 | AN9: 4 | AO9: Credicorp Capital Chile
H10: 16 | I10: 5 | J10: ASB - Panama | AM10: 16 | AN10: 4 | AO10: ASB - Panama
H11: 16 | I11: 5 | J11: Credicorp Capital Perú | AM11: 16 | AN11: 4 | AO11: Credicorp Capital Perú
H12: 16 | I12: 5 | J12: Credicorp Capital USA | AM12: 16 | AN12: 4 | AO12: Credicorp Capital USA
H13: 5 | I13: 4 | J13: Pacifico-Prestadoras de Salud | K13: Akamai | L13: ='03-VolumetriaCredActualizada'!G14 -> 0.06636 | M13: ='03-VolumetriaCredActualizada'!K14 -> 78 | N13: ='03-VolumetriaCredActualizada'!O14 -> 391.96 | X13: x | Y13: x | Z13: x | AM13: 5 | AN13: 5 | AO13: Pacifico-Prestadoras de Salud | AP13: Akamai | AT13: x
H14: 4 | I14: 6 | J14: Pacifico Salud/EPS | K14: Akamai | L14: ='03-VolumetriaCredActualizada'!G13 -> 0.01301 | M14: ='03-VolumetriaCredActualizada'!K13 -> 16 | N14: ='03-VolumetriaCredActualizada'!O13 -> 0.061 | AA14: x | AB14: x | AC14: x | AM14: 4 | AN14: 6 | AO14: Pacifico Salud/EPS | AP14: Akamai | AU14: x
H15: 9 | I15: 7 | J15: YAPE - Perú | K15: Imperva | L15: 0.019591243 | M15: 11 | N15: 1970.909 | AA15: x | AB15: x | AC15: x | AM15: 9 | AN15: 7 | AO15: YAPE - Perú | AP15: Imperva | AU15: x
H16: 11 | I16: 8 | J16: YAPE - Bolivia | K16: Imperva | L16: ='03-VolumetriaCredActualizada'!G11 -> 0.07 | M16: ='03-VolumetriaCredActualizada'!K11 -> 1 | N16: ='03-VolumetriaCredActualizada'!O11 -> 2.25 | AD16: x | AE16: x | AF16: x | AM16: 11 | AN16: 8 | AO16: YAPE - Bolivia | AP16: Imperva | AV16: x
H17: 10 | I17: 9 | J17: BCP - Bolivia | K17: Radware | L17: ='03-VolumetriaCredActualizada'!G12 -> 0.06 | M17: ='03-VolumetriaCredActualizada'!K12 -> 6 | N17: ='03-VolumetriaCredActualizada'!O12 -> 1.25 | AD17: x | AE17: x | AF17: x | AM17: 10 | AN17: 9 | AO17: BCP - Bolivia | AP17: Radware | AV17: x
H18: 15 | I18: 10 | J18: IO | K18: AWS Firewall | L18: 0.0089 | M18: 6 | N18: 163.6 | AG18: x | AH18: x | AI18: x | AM18: 15 | AN18: 10 | AO18: IO | AP18: AWS Firewall | AW18: x
H19: 2 | I19: 11 | J19: Pacifico Seguros y Pensiones | K19: Azure Frootdoor | L19: ='03-VolumetriaCredActualizada'!G16 -> 0.02 | M19: ='03-VolumetriaCredActualizada'!K16 -> 33 | N19: ='03-VolumetriaCredActualizada'!O16 -> 70 | AG19: x | AH19: x | AI19: x | AM19: 2 | AN19: 11 | AO19: Pacifico Seguros y Pensiones | AP19: Azure Frootdoor | AW19: x
H20: 3 | I20: 12 | J20: Prima AFP | K20: Azure Frootdoor | L20: ='03-VolumetriaCredActualizada'!G17 -> 0.06 | M20: ='03-VolumetriaCredActualizada'!K17 -> 21 | N20: ='03-VolumetriaCredActualizada'!O17 -> 52 | AG20: x | AH20: x | AI20: x | AM20: 3 | AN20: 12 | AO20: Prima AFP | AP20: Azure Frootdoor | AW20: x
H21: 6 | I21: 13 | J21: Culqui | K21: AWS Firewall | L21: ='03-VolumetriaCredActualizada'!G18 -> 0.015 | M21: ='03-VolumetriaCredActualizada'!K18 -> 43 | N21: ='03-VolumetriaCredActualizada'!O18 -> 181.6 | AG21: x | AH21: x | AI21: x | AM21: 6 | AN21: 13 | AO21: Culqui | AP21: AWS Firewall | AW21: x
H22: 7 | I22: 14 | J22: BCP Miami | K22: Azure Frootdoor | L22: ='03-VolumetriaCredActualizada'!G15 -> 9.99701e-06 | M22: ='03-VolumetriaCredActualizada'!K15 -> 6 | N22: ='03-VolumetriaCredActualizada'!O15 -> 0.15963 | AG22: x | AH22: x | AI22: x | AM22: 7 | AN22: 14 | AO22: BCP Miami | AP22: Azure Frootdoor | AW22: x
H23: 8 | I23: 15 | J23: Monokera | K23: AWS Firewall | L23: ='03-VolumetriaCredActualizada'!G19 -> 0.000144 | M23: ='03-VolumetriaCredActualizada'!K19 -> 19 | N23: ='03-VolumetriaCredActualizada'!O19 -> 6.08 | AG23: x | AH23: x | AI23: x | AM23: 8 | AN23: 15 | AO23: Monokera | AP23: AWS Firewall | AW23: x
H24: 14 | I24: 16 | J24: Tyba | K24: AWS Firewall | L24: ='03-VolumetriaCredActualizada'!G20 -> 0.015 | M24: ='03-VolumetriaCredActualizada'!K20 -> 15 | N24: ='03-VolumetriaCredActualizada'!O20 -> 13 | AG24: x | AH24: x | AI24: x | AM24: 14 | AN24: 16 | AO24: Tyba | AP24: AWS Firewall | AW24: x
O25: =SUM(L5) -> 0 | P25: =SUM(M5) -> 11 | Q25: =SUM(N5) -> 120 | R25: =SUM(L6)+SUM(O25) -> 0.00187 | S25: =SUM(M6)+SUM(P25) -> 58 | T25: =SUM(N6)+SUM(Q25) -> 1370 | U25: =SUM(L7)+SUM(R25) -> 0.00687 | V25: =SUM(M7)+SUM(S25) -> 64 | W25: =SUM(N7)+SUM(T25) -> 1380.5142 | X25: =SUM(L8:L12)+SUM(U25) -> 0.01887 | Y25: =SUM(M8:M12)+SUM(V25) -> 171 | Z25: =SUM(N8:N12)+SUM(W25) -> 1400.5842 | AA25: =SUM(L14:L15)+SUM(X25) -> 0.051471243 | AB25: =SUM(M14:M15)+SUM(Y25) -> 198 | AC25: =SUM(N14:N15)+SUM(Z25) -> 3371.5542 | AD25: =SUM(L16:L17)+SUM(AA25) -> 0.18147124 | AE25: =SUM(M16:M17)+SUM(AB25) -> 205 | AF25: =SUM(N16:N17)+SUM(AC25) -> 3375.0542 | AG25: =SUM(L18:L24)+AD25 -> 0.30052524 | AH25: =SUM(M18:M24)+AE25 -> 348 | AI25: =SUM(N18:N24)+AF25 -> 3861.4938

Sheet 03-VolumetriaCredActualizada
K1: R | L1: R | M1: R | O1: R | AZ1: Licencias
G2: VOLUMETRIA(Info Relevada) | S2: VOLUMETRIA(Validada con fabricante) | AF2: CAPACIDADES WAAP | AR2: Homologacion Capacidades Tecnologia / Partnumber / SKU | AZ2: Homologacion Tecnologia | BE2: Habilitacion Opcional | BJ2: Servicios
A3: N° | B3: N° prioridad | C3: Empresa | D3: APP (Nro) | E3: WAF AS-IS | F3: PRESUPUESTO ANUAL | G3: Throughput (mensual) Gbps | H3: Ancho de Banda (mensual) Gbps | I3: Dominio | J3: Sub Dominios | K3: Cantidad de aplicaciones (FQDN) | L3: Cantidad de Aplicaciones FQDN en API Security | M3: API Protection / API Security Request (M x Mes) | N3: Millones de Request (M) (mensual / antibot) | O3: Millones Request WAF (M) (mensual) | P3: Data Transfer (TB) (mensual) | Q3: Request Size (mensual) | R3: Response Size (mensual) | S3: Throughput (mensual) Gbps | T3: Ancho de Banda (mensual) Gbps | U3: Dominio | V3: Sub Dominios | W3: Cantidad de aplicaciones (FQDN) | X3: Cantidad de Aplicaciones FQDN en API Security | Y3: API Protection / API Security Request (M x Mes) | Z3: Millones de Request (M) (mensual / antibot) | AA3: Millones Request WAF (M) (mensual) | AB3: Millones Request Antibot+WAF (M) (mensual) | AC3: Data Transfer (TB) (mensual) | AD3: Request Size (mensual) | AE3: Response Size (mensual) | AF3: Web Application Firewall | AG3: Bot Protection (ABP) en WAP (Basic) | AH3: Bot Protection Advanced (ABP) | AI3: Client Side Protection (CSP) | AJ3: Account Take Over (ATO) - Basic | AK3: Account Take Over (ATO) - Advanced | AL3: API Protection / API Security (Basic) | AM3: API Protection / API Security - Advanced | AN3: Anti DDoS (Layer 7) | AO3: Certificate Manager y mTLS | AP3: Content Delivery Network (CDN) | AQ3: Comentario de subsidiaria | AR3: Web Application Firewall | AS3: Bot Protection (ABP) | AT3: Client Side Protection (CSP) | AU3: Account Take Over (ATO) | AV3: API Protection / API Security | AW3: Anti DDoS (Layer 7) | AX3: Certificate Manager y mTLS | AY3: Content Delivery Network (CDN) | AZ3: Web Application Firewall | BA3: Bot Protection (ABP) | BB3: Anti DDoS (Layer 7) | BC3: Certificate Manager y mTLS | BD3: Content Delivery Network (CDN) | BE3: API Protection | BF3: API Security | BG3: Client Side Protection (CSP) | BH3: Account Take Over (ATO) | BI3: Add-Ons | BJ3: Servicios - Implementacion | BK3: Servicios - Migracion | BL3: Servicios - Operación
A4: 10 | B4: 3 | C4: Mi Banco Colombia - Entregado | D4: 6 | E4: Imperva | G4: 0.005 | H4: 0.1 | K4: 6 | L4: 2 | M4: Cuenta con licencia activa para: * 2 dominios/publicaciones 10M | N4: no aplica | O4: 10.51421 | P4: 0.25158 | Q4: sin respuesta | R4: sin respuesta | AF4: A | AH4: A | AI4: A | AJ4: A | AL4: A | AN4: A | AO4: NA | AP4: A | AQ4: Cuenta con licencia Activa, pero su modelo de licenciamiento es por dominio.
A5: 10 | B5: 3 | C5: Mi Banco Colombia - Revisado | E5: Imperva | G5: 0,100000 | H5: no aplica por ser SaaS | K5: 6 | P5: 11 | AF5: A | AG5: A | AH5: NA | AI5: A | AJ5: A | AK5: sin referencia | AL5: A | AM5: NA | AN5: A | AO5: A | AP5: A
A6: 20 | B6: 16 | C6: Yape | D6: 11 | E6: Imperva | G6: 0.019591243 | H6: 0.037040741 | K6: 11 | L6: no brindo informacion | M6: no brindo informacion | N6: 0.012197 | O6: 1970.909 | P6: 3.0204852 | Q6: No Aplica | R6: No Aplica | AF6: no brinda informacion | AH6: no brinda informacion | AI6: no brinda informacion | AJ6: no brinda informacion | AL6: no brinda informacion | AN6: no brinda informacion | AO6: no brinda informacion | AP6: no brinda informacion | AQ6: no brinda informacion
A7: 1 | B7: 4 | C7: Mi Banco Peru | D7: 11 | E7: Cloudflare | G7: 0.0029 GBPS | H7: no aplica por ser SaaS | I7: 1 | J7: 10 | K7: 11 | L7: 5 (MTLS) | M7: 78.67 | N7: 123.49 | O7: 120 | P7: 0.676 TB | R7: 676.24 GB | AF7: A | AG7: A | AH7: X | AI7: A | AJ7: A | AK7: X | AL7: A | AM7: X | AN7: A | AO7: A | AP7: A | AR7: APP-SRV-100MB | AT7: APP-SRV-100MB | AV7: APP-SRV-100MB
A8: 1 | B8: 4 | C8: Mi Banco Peru - Revisado | D8: 11 | E8: Cloudflare | G8: 6.34 MBPS | H8: no aplica por ser SaaS | I8: 1 | J8: 10 | K8: 12 (12 contratados 9 activos) | L8: 14 (actualmente 5 dedicados + 8 custom) | M8: 120 MM | N8: 120 MM | O8: 120 MM | P8: 2TB | Q8: 120 MM | R8: 120 MM | AF8: A | AG8: A | AH8: NA | AI8: NA | AJ8: A | AK8: NA | AL8: NA | AM8: NA | AN8: A | AO8: A | AP8: A
A9: 11 | B9: 2 | C9: Tenpo Chile | D9: 47 | E9: Cloudflare | G9: 0.00187 | H9: no aplica por ser SaaS | I9: 8 | K9: 47 | L9: 47 | M9: Cuenta con licencia Activa * 1.3 B (1300MM) request promedio mensual | N9: no aplica | O9: 1250 | P9: sin respuesta | Q9: sin respuesta | R9: sin respuesta | AF9: A | AH9: NA | AI9: NA | AJ9: NA | AL9: A | AN9: A | AO9: A | AP9: A
A10: 13 | B10: 5 | C10: Credicorp Capital | D10: 107 | E10: Cloudflare | G10: 0.012 | H10: no aplica por ser SaaS | I10: 19 | J10: 160 | K10: 107 | L10: 2 | M10: 6.09 | N10: sin informacion | O10: 20.07 | P10: 26.97 | Q10: sin respuesta | R10: sin respuesta | AF10: A | AH10: A | AI10: NA | AJ10: NA | AL10: A | AN10: A | AO10: A | AP10: A | AQ10: sobre el api security 6.090.000 / 5 países = 1.218.000/mes por país.
A11: 9 | B11: 9 | C11: YAPE Bolivia | D11: 1 | E11: Radware | G11: 0.07 | H11: 0.15 | I11: 1 | K11: 1 | L11: 0 | M11: No cuenta con modulo; actualmente en exploratorio con 10 apis en desarrollo | N11: No Aplica | O11: 2.25 | P11: 4.75 | Q11: 180 KB | R11: 400 KB | AF11: A | AH11: F | AI11: A | AJ11: F | AL11: A | AN11: A | AO11: A | AP11: NA
A12: 22 | B12: 8 | C12: BCP Bolivia | D12: 6 | E12: Radware | G12: 0.06 | H12: 0.06 | K12: 6 | L12: 2 | M12: No cuenta con modulo; actualmente en exploratorio con 10 apis en desarrollo | N12: No Aplica | O12: 1.25 | P12: 3.75 | Q12: 170 KB | R12: 395 KB | AF12: A | AI12: A | AL12: A | AN12: A | AO12: A | AP12: NA | AQ12: Cuentan con licencias activas, estan en entorno de desarrollo explorando como usar el modulo de api security con 10 apis (109MM de request )
A13: 4 | B13: 7 | C13: Pacifico Salud/EPS | D13: 16 | E13: Akamai | G13: 0.01301 | H13: no aplica por ser SaaS | I13: 3 | J13: 13 | K13: 16 | L13: 41 Prod 118 Test | M13: No cuenta con modulo | N13: 6.23 | O13: =0.03+0.031 -> 0.061 | P13: 0.18599292 | AF13: A | AH13: A | AI13: NA | AJ13: NA | AL13: F | AN13: A | AO13: A | AP13: A | AQ13: No cuenta con modulo de API Protecion, usan el WAF tradicional + antibot + DoS
A14: 5 | B14: 6 | C14: Pacifico Prestadoras de Salud | D14: 78 | E14: Akamai | G14: 0.06636 | H14: no aplica por ser SaaS | I14: 20 | J14: 58 | K14: 78 | L14: No cuenta con modulo | M14: No cuenta con modulo | N14: 65 | O14: 391.96 | P14: 14.66 | AF14: A | AH14: A | AI14: NA | AJ14: NA | AL14: F | AN14: A | AO14: NA | AP14: A | AQ14: No cuenta con modulo de API Protecion, usan el WAF tradicional
A15: 7 | B15: 10 | C15: BCP Miami | D15: 6 | E15: Frontdoor | G15: 9.99701e-06 | H15: no aplica por ser SaaS | I15: 1 | J15: 0 | K15: 6 | L15: 0 | M15: 0 | N15: no aplica | O15: 0.15963 | P15: 3.347 | Q15: sin respuesta | R15: sin respuesta | AF15: A | AH15: A | AI15: NA | AJ15: NA | AL15: NA | AN15: A | AO15: NA | AP15: A
A16: 2 | B16: 12 | C16: Pacifico Seguros | D16: 33 | E16: Frontdoor | G16: 0.02 | H16: no aplica por ser PaaS | I16: 2 | J16: 28 | K16: 33 | L16: (01) api.pacifico.com.pe | M16: 187 | N16: 70 | O16: 70 | P16: 5.4 | Q16: 165.9 GB | R16: 5.4 TB | AF16: A | AH16: A | AI16: NA | AJ16: NA | AL16: F | AN16: A | AO16: NA | AP16: A | AQ16: a nivel de api security, usan defender y waf tradicional como complementario. La columna J incluye un crecimiento del 10% de FQDN al 09.07.2026
A17: 3 | B17: 13 | C17: Prima AFP | D17: 21 | E17: Frontdoor | G17: 0.06 | H17: no aplica por ser PaaS | I17: 2 | J17: 17 | K17: 21 | L17: (01) api.turesumenprima.com.pe | M17: 54 | N17: 426 | O17: 52 | P17: 19.400653 | Q17: 442.9 GB | R17: 19.4 TB | AF17: A | AH17: A | AI17: NA | AJ17: NA | AL17: F | AN17: A | AO17: NA | AP17: A | AQ17: a nivel de api security, usan defender y waf tradicional como complementario. La columna J incluye un crecimiento del 10% de FQDN al 09.07.2026 | AR17: CLOUDF-WAF | AX17: CLODF-CDN-100MB
A18: 6 | B18: 15 | C18: Culqi | D18: 43 | E18: AWS Firewall | G18: 0.015 | H18: no aplica por ser SaaS | I18: 3 | J18: 76 | K18: 43 | L18: 33 | M18: 111.9 | N18: no aplica | O18: 181.6 | P18: 4.53 | Q18: sin respuesta | R18: sin respuesta | AF18: A | AH18: A | AI18: NA | AJ18: A | AL18: F | AN18: A | AO18: A | AP18: A | AQ18: No cuenta con modulo API security, usan el WAF como API Protection Usan Cloudfront para CDN
A19: 8 | B19: 11 | C19: Monokera | D19: 19 | E19: AWS Firewall | G19: 0.000144 | H19: no aplica por ser SaaS | K19: 19 | L19: 7 | M19: 3.87 | N19: no aplica | O19: 6.08 | P19: 0.00018 | AF19: A | AH19: F | AI19: F | AJ19: A | AL19: A | AN19: F | AO19: F | AP19: F
A20: 12 | B20: 14 | C20: TYBA | D20: 15 | E20: AWS Firewall | G20: 0.015 | H20: no aplica por ser SaaS | K20: 15 | L20: 15 | M20: 13M | N20: 13 | O20: 13 | P20: sin respuesta | Q20: sin respuesta | R20: sin respuesta | AF20: A | AH20: NA | AI20: NA | AJ20: NA | AL20: A | AN20: F | AO20: NA | AP20: NA | AQ20: CND = Se maneja con CloudFront Certificate Manager = AWS Certificate Manager AntiDDOS = Tenemos protección AWS Shield Standar, pero nos gustaria revisar a futuro una mas avanzada
A21: 21 | B21: 17 | C21: IO | D21: 6 | E21: AWS Firewall | G21: 0.0089 | H21: no aplica por ser SaaS | K21: 6 | L21: 61 | M21: No cuenta con modulo | N21: 0.05 | O21: 163.6 | P21: 2.617 | Q21: 818 GB | R21: 4951 GB | AF21: A | AH21: A | AI21: NA | AJ21: NA | AL21: F | AN21: NA | AO21: NA | AP21: NA (Se usa cloudfront) | AQ21: No cuenta con modulo de Api security, lo realizan a traves del WAF.
D22: =SUM(D7:D21) -> 420
K25: IMPERVA | M25: CLOUDFLARE
H26: imperva | K26: Cantidad de aplicaciones (FQDN) | M26: Cantidad de aplicaciones (FQDN)
H27: imperva | K27: Throughput (mensual) Gbps | M27: Throughput (mensual) Gbps
M28: Data Transfer (TB) (mensual)

Sheet 04-HomologacionCapacidades
A1: CAPACIDADES WAAP | B1: CAPACIDAD / MODULO | C1: DESCRIPCION CREDICORP | D1: Nueva Definicion | E1: CASOS DE USO | F1: DESCRIPCION FABRICANTE | G1: funcionalidades cubiertas por el FABRICANTE
B2: Web Application Firewall | C2: Módulo de Firewall de aplicaciones, diseñado para protección contra OWASP Top10 | D2: Capacidad de inspeccionar, analizar y controlar el tráfico HTTP/HTTPS dirigido a aplicaciones web, identificando y mitigando ataques, abusos y vulnerabilidades de capa de aplicación mediante políticas de seguridad, firmas, modelos de detección y controles configurables, independientemente de dónde se encuentren alojadas las aplicaciones protegidas. | E2: • Protección OWASP Top 10 • Reglas administradas • Reglas personalizadas • Protección frente a técnicas de evasión • Detección de ataques SQLi • Detección de ataques XSS • Detección de RCE • Detección de Path Traversal • Logging y auditoría • Gestión de falsos positivos • Integración SIEM/SOAR • Protección de aplicaciones web y endpoints HTTP • Bloqueo y monitoreo • Protección ante firmas conocidas • Protección HTTP/HTTPS • Excepciones y exclusiones • Protección de formularios y parámetros • Protección Zero-Day • Machine Learning Detection • Attack Scoring • Behavioral Analysis • Threat Intelligence integrada • Detección de evasión avanzada • Virtual Patching automático • Detección de anomalías HTTP • Sensitive Data Detection • Exposed Credential Detection • Malware Upload Detection • Protección gRPC • Protección WebSockets • Recomendación automática de reglas • Integración CI/CD • Terraform/IaC
B3: Bot Protection (ABP) en WAP - Basic | C3: Módulo de Prevención contra bots, captcha, necesario para detección y mitigación de actividad automatizada generada por bots maliciosos | D3: Identificación y mitigación de bots conocidos y automatización simple mediante reglas, reputación y desafíos. | E3: • Detección basada en firmas • Reputación IP/ASN • User-Agent filtering • Allowlist de Good Bots • Blocklist configurable • JavaScript Challenge • CAPTCHA o mecanismo equivalente • Rate Limiting para automatización evidente • Protección básica contra scraping • Protección básica contra fuerza bruta • Dashboards de tráfico humano vs bot
B4: Bot Protection - Advanced (ABP) | C4: Módulo de Prevención contra bots, captcha, necesario para detección y mitigación de actividad automatizada generada por bots maliciosos | D4: Detección y mitigación de automatización sofisticada basada en comportamiento, identidad, dispositivo y modelos adaptativos de riesgo. Detección conductual, fingerprinting, ML, credential stuffing y fraude automatizado. | E4: • Device Fingerprinting • Browser Fingerprinting • Behavioral Analysis • Machine Learning Detection • Bot Scoring • Session Analysis • Human Verification adaptativa • Detección de evasión de CAPTCHA • Credential Stuffing Protection • Carding Protection • Fake Account Creation Protection • Signup Abuse Protection • Inventory Hoarding Protection • Scalping Protection • Mobile SDK Protection • API Bot Protection • Respuestas dinámicas según riesgo
B5: Client Side Protection (CSP) | C5: Módulo para la protección al cliente final, capaz de detectar actividades maliciosas en el navegador del usuario | D5: Capacidad para descubrir, monitorear, evaluar y controlar scripts, librerías, recursos y comunicaciones ejecutadas en el navegador del usuario final, con el objetivo de detectar modificaciones no autorizadas, ataques a la cadena de suministro web, robo de datos y exfiltración de información desde la capa cliente. | E5: • Protección en el navegador clientes • Inventario de Scripts: Descubrimiento de scripts propios y de terceros. • Descubrimiento de Dependencias: Identificación de dominios externos utilizados por la aplicación. • Monitoreo de Cambios: Detección de scripts agregados, modificados o eliminados. • Alertas de Cambios: Notificación de actividades sospechosas. • Visibilidad de Terceros: Identificación de proveedores externos ejecutándose en el navegador. • Baseline de Scripts: Construcción de una línea base autorizada. • Reporting: Visibilidad por aplicación, dominio o página. • Detección de Magecart: Identificación de ataques de skimming digital. Detección de Supply Chain Attacks: Identificación de bibliotecas comprometidas. • Script Integrity Monitoring: Validación continua de integridad. • Exfiltration DetectionDetección de transferencia no autorizada de datos. • Exfiltration Blocking: Bloqueo de intentos de extracción de información. • CSP Management: Gestión y generación de Content Security Policy. • Risk Scoring: Clasificación de riesgo por script. • Behavioral AnalysisAnálisis del comportamiento de scripts. • Sensitive Data MonitoringIdentificación de acceso a datos sensibles. • PCI DSS Monitoring: Controles específicos para cumplimiento PCI DSS 4.0. Proteger contra: Magecart Formjacking Supply Chain Attack Robo de tarjetas Robo de credenciales Exfiltración de datos Scripts comprometidos JavaScript malicioso
B6: Account Take Over (ATO) - Basic | C6: Capa de seguridad sobre login, brinda protección contra password spray y detección contra filtraciones de usuarios y contraseñas | D6: Capacidad para detectar y bloquear intentos de acceso no autorizados a cuentas mediante el uso de credenciales comprometidas, automatización simple y controles de autenticación orientados a reducir el riesgo de apropiación de cuentas. | E6: • Credential Stuffing Detection • Brute Force Protection • Password Spraying Detection • Rate Limiting sobre procesos de login • Detección de credenciales expuestas o comprometidas • IP Reputation • ASN Reputation • Country Blocking • CAPTCHA / JS Challenge • Bot Detection básica • Login Monitoring • Alertas de intentos de autenticación sospechosos
B7: Account Take Over (ATO) - Advanced | D7: Capacidad para prevenir la apropiación fraudulenta de cuentas mediante la correlación de señales de identidad, dispositivo, comportamiento, sesión y riesgo, aplicando respuestas adaptativas y protección continua durante todo el ciclo de autenticación y uso de la cuenta. | E7: • Behavioral Authentication Analytics • User Risk Scoring • Bot Risk Scoring • Device Fingerprinting • Browser Fingerprinting • Session Risk Analysis • Session Hijacking Detection • Impossible Travel Detection • UEBA (User & Entity Behavior Analytics) • Continuous Authentication Validation • Adaptive Authentication • Integration con IdP / IAM • Identity Risk Correlation • Fraud Detection • Mobile Device Trust Validation • ATO Campaign Detection • Account Abuse Analytics
B8: API Protection / API Security - Basic | C8: Módulo de protección especializado para APIs (seguridad avanzada de api's), rate limiting | D8: Protección fundamental de APIs conocidas mediante controles de seguridad en tiempo de ejecución que validan solicitudes, autenticación y abuso básico. * Protege APIs conocidas * Valida solicitudes * Autenticación * Rate Limiting simple * OWASP API Top 10 * REST tradicional | E8: • Inventario manual o importado de APIs • Protección REST básica • Validación de autenticación (API Key, JWT, OAuth) • Validación de esquemas OpenAPI cargados manualmente • Protección frente a OWASP API Security Top 10 • WAF aplicado a endpoints API • Rate Limiting por IP o endpoint • Protección DDoS L7 • Registro y monitoreo por endpoint • Detección básica de datos sensibles
B9: API Protection / API Security - Advanced | C9: Módulo de protección especializado para APIs (seguridad avanzada de api's), rate limiting | D9: Protección avanzada de APIs basada en descubrimiento continuo, análisis de postura, comportamiento, lógica de negocio y riesgos asociados a APIs desconocidas o mal configuradas. * Descubre APIs desconocidas * Analiza comportamiento * Postura de autenticación * Rate Limiting contextual * Lógica de negocio y BOLA * REST + GraphQL + gRPC | E9: • Descubrimiento automático de APIs (Shadow APIs) • Descubrimiento de Zombie APIs • Aprendizaje automático de esquemas • API Posture Management • Evaluación de autenticación inconsistente o ausente • Detección de BOLA/BFLA • Detección de abuso de lógica de negocio • Behavioral Analytics • Sequence Analysis • Detección de exfiltración de datos • Sensitive Data Discovery por endpoint • Protección GraphQL • Protección gRPC • Rate Limiting contextual (usuario, token, sesión) • Protección contra bots sobre APIs • Recomendaciones automáticas de políticas • Analítica avanzada de rendimiento y comportamiento
B10: Anti DDoS (Layer 7) | C10: Capa de mitigación ante ataques de denegación de servicio y volumetría a las aplicaciones web | D10: Garantizar la disponibilidad de aplicaciones y APIs frente a ataques volumétricos, de agotamiento de recursos o abuso de protocolos HTTP/HTTPS. Capacidad para detectar, analizar y mitigar ataques de denegación de servicio dirigidos a aplicaciones web y APIs, protegiendo la disponibilidad de los servicios mediante mecanismos automáticos de identificación de anomalías, absorción de tráfico malicioso y aplicación de políticas específicas de capa de aplicación. | E10: • Aplicar umbrales de forma manual y automática según la tendencia de conexiones recibidas. • Rate Limiting integrado • Detección automática de ataques L7 • Mitigación automática en tiempo real • Protección HTTP/HTTPS • Protección de APIs • Protección contra HTTP Flood • Protección contra Slow HTTP Attacks • Protección contra ataques basados en sesiones • Protección por URL o endpoint • Detección basada en comportamiento • Análisis de anomalías • Adaptive DDoS Mitigation • Machine Learning Detection • Challenge dinámico según riesgo • Protección específica GraphQL • Protección específica gRPC • Mitigación por sesión o identidad • Detección de ataques de baja intensidad (Low-and-Slow) • Dashboards y reporting de ataques
B11: Certificate Manager y mTLS | C11: * Capa para la gestión de certificados de presentación y MTLS. Administra y limita los algoritmos de cifrado soportados para permitir una conexión. * Inspección de SSL. | D11: Capacidad para administrar el ciclo de vida de certificados digitales y aplicar autenticación criptográfica mutua entre clientes, servicios, APIs, garantizando comunicaciones seguras, autenticación fuerte y protección de identidades de máquina. | E11: • Permite importar certificados SSL y MTLS propios en diferentes formatos(.cer, .pfx) • Permite asociar certificados MTLS a varias URL en simultaneo • Permite restringir la conexión SSL/TLS basado en fingerprint • Permite especificar los Cipher Suite soportados para la conexión SSL/TLS. • Emisión de certificados • Importación de certificados • Renovación automática de certificados • Gestión de ciclo de vida • Inventario de certificados • Alertas de expiración • TLS moderno • TLS cliente-servidor • TLS hacia origen • Soporte certificados públicos y privados • Auditoría de certificados
B12: Content Delivery Network (CDN) | C12: Capacidad para brindar aceleración de tráfico y mejorar la experiencia de usuario mediante mecanismos como caché, páginas personalizadas y redirección http-https | D12: Mejorar la experiencia del usuario, reducir tiempos de respuesta y aumentar resiliencia y escalabilidad de aplicaciones y servicios digitales. Capacidad para distribuir, acelerar y optimizar la entrega de contenido y aplicaciones desde una red distribuida geográficamente, reduciendo latencia, mejorando disponibilidad y disminuyendo la carga sobre los sistemas de origen. | E12: • Permite aplicar diferente tipos caching para la aceleración de contenido al usuario final • Permite personalizar páginas de error y waiting rooms. • Caché de contenido estático • Caché de contenido dinámico • Aceleración de aplicaciones • Offload de tráfico al origen • Optimización de rutas • Compresión de contenido • Optimización de imágenes • Edge Delivery • Anycast Delivery • Protección del origen • Integración con DNS • Integración con WAF • Integración con DDoS Protection • Purga de caché • Cache Analytics
B13: Comentario de subsidiaria | C13: Modulos o features adicionales que pueda contar la plataforma | D13: Componentes que se consideren adicionales, opcionales, para la evaluacion, que no estan incluidas en las capacidades mencionadas anteriormente.
B19: CAPACIDADES WAAP
A20: N° | B20: FQDN | C20: Web Application Firewall | D20: Bot Protection (ABP) en WAP - Basic | E20: Bot Protection - Advanced (ABP) | F20: Client Side Protection (CSP) | G20: Account Take Over (ATO) - Basic | H20: Account Take Over (ATO) - Advanced | I20: API Protection / API Security - Basic | J20: API Protection / API Security - Advanced | K20: Anti DDoS (Layer 7) | L20: Certificate Manager y mTLS | M20: Content Delivery Network (CDN) | N20: Comentario de subsidiaria
A21: 9 dominios | K21: 2TB & 100MM | L21: 7 universal (5 dedicados) 6 custom mtls (para 17 incluso) | M21: 120 MM
A24: N° | B24: Empresa | C24: APP (Nro) | D24: WAF AS-IS | E24: Throughput (mensual) Gbps | F24: Ancho de Banda (mensual) Gbps | G24: Dominio | H24: Sub Dominios | I24: Cantidad de aplicaciones (FQDN) | J24: Cantidad de Aplicaciones FQDN en API Security | K24: API Protection / API Security Request (M x Mes) | L24: Millones de Request (M) (mensual / antibot) | M24: Millones Request WAF (M) (mensual) | N24: Millones Request Antibot+WAF (M) (mensual) | O24: Data Transfer (TB) (mensual) | P24: Request Size (mensual) | Q24: Response Size (mensual)
A25: 1 | B25: Mi Banco Peru | C25: 11 | D25: Cloudflare | E25: 0.0029 | F25: no aplica por ser SaaS | G25: 1 | H25: 10 | I25: 11 | J25: 5 (MTLS) | K25: 78.67 | L25: 123.49 | M25: 120 | N25: 243.49 | O25: 0.676 TB | Q25: 676.24 GB
A26: 1 | B26: Mi Banco Peru - Revisado | I26: 12 (contratados 9 activos)

Sheet Hoja3
A1: Tabla propuesta de capacidades WAAP
A3: Dominio | B3: Capacidad / Módulo | C3: Descripción Agnóstica | D3: Funcionalidades Esenciales | E3: Funcionalidades Avanzadas
A4: WAAP Core | B4: Web Application Firewall (WAF) | C4: Protección de aplicaciones web frente a ataques de capa 7 mediante inspección de tráfico y aplicación de políticas de seguridad. | D4: OWASP Top 10, reglas gestionadas, reglas personalizadas, logging, virtual patching básico. | E4: ML/anomaly detection, attack scoring, detección de credenciales expuestas, malware upload scanning, protección gRPC/WebSocket.
A5: WAAP Core | B5: Application DDoS Protection (L7) | C5: Protección contra ataques de denegación de servicio dirigidos a aplicaciones y APIs. | D5: Detección y mitigación automática L7, protección HTTP/HTTPS, dashboards. | E5: Detección adaptativa, mitigación basada en comportamiento, protección granular por endpoint/API.
A6: WAAP Core | B6: Bot Management & Automated Abuse Protection | C6: Identificación y gestión de tráfico automatizado legítimo y malicioso. | D6: Firmas, reputación IP, JS Challenge, CAPTCHA, allow/deny list, protección básica contra scraping. | E6: Fingerprinting, behavioral analysis, bot scoring, ATO, credential stuffing, carding, signup abuse, mobile bot protection.
A7: WAAP Core | B7: API Security | C7: Descubrimiento, protección y control de APIs durante todo su ciclo de vida. | D7: Inventario conocido, autenticación, validación de esquema, rate limiting, logging de APIs. | E7: API Discovery, posture management, detección BOLA/BFLA, behavioral analytics, protección de lógica de negocio.
A8: WAAP Core | B8: Client-Side Security | C8: Protección de scripts y componentes ejecutados en el navegador del usuario. | D8: Inventario de scripts, monitoreo de cambios, alertas. | E8: Detección de Magecart, CSP asistido, control de exfiltración, integridad de scripts.
A9: API Security (recomendación: dividirlo)
A11: No dejar una sola fila "API Protection"
B13: Subcapacidad | C13: Descripción | D13: Esencial | E13: Avanzada
A14: API Security | B14: API Discovery | C14: Identificación de APIs y endpoints expuestos. | D14: Inventario manual o importado. | E14: Descubrimiento automático de APIs shadow, zombie y desconocidas.
A15: API Security | B15: API Schema Management | C15: Uso de modelos positivos basados en especificaciones. | D15: Carga manual OpenAPI. | E15: Aprendizaje automático de esquemas y detección de desviaciones.
A16: API Security | B16: API Authentication Validation | C16: Verificación de autenticación utilizada por APIs. | D16: API Key, JWT, OAuth. | E16: mTLS, posture assessment y análisis de autenticación inconsistente.
A17: API Security | B17: API Authorization Security | C17: Protección contra fallas de autorización. | D17: Reglas personalizadas. | E17: Detección de BOLA/BFLA y abuso de privilegios.
A18: API Security | B18: API Data Protection | C18: Protección de información sensible expuesta por APIs. | D18: Detección básica de datos sensibles. | E18: Clasificación contextual y detección de exfiltración.
A19: API Security | B19: API Abuse Protection | C19: Protección frente a abuso y automatización. | D19: Rate limiting, DDoS, WAF. | E19: Análisis de secuencia, lógica de negocio y comportamiento.
A20: API Security | B20: API Analytics & Visibility | C20: Observabilidad y monitoreo. | D20: Volumen, errores y latencia. | E20: Análisis de secuencias, baseline y anomalías.
A21: API Security | B21: API Protocol Security | C21: Protección de protocolos específicos. | D21: REST. | E21: GraphQL, gRPC y APIs asíncronas.
A23: Bot Management (separación recomendada)
B25: Subcapacidad | C25: Descripción | D25: Esencial | E25: Avanzada
A26: Bot Management | B26: Bot Detection | C26: Identificación básica de bots. | D26: Firmas, reputación IP, User-Agent. | E26: Huella de dispositivo y navegador.
A27: Bot Management | B27: Good Bot Management | C27: Gestión de bots legítimos. | D27: Allowlist básica. | E27: Clasificación automática y verificación continua.
A28: Bot Management | B28: Bot Classification | C28: Clasificación humano/bot. | D28: Reglas estáticas. | E28: Machine Learning y Behavioral Models.
A29: Bot Management | B29: Bot Scoring | C29: Asignación de riesgo. | D29: No requerido. | E29: Bot Score dinámico.
A30: Bot Management | B30: Scraping Protection | C30: Protección contra extracción automatizada. | D30: Bloqueo básico. | E30: Detección avanzada de scraping distribuido.
A31: Bot Management | B31: Credential Stuffing Protection | C31: Protección de credenciales. | D31: Rate limiting. | E31: Detección de credenciales comprometidas y ATO.
A32: Bot Management | B32: Account Takeover Protection | C32: Protección de cuentas. | D32: Desafíos y bloqueo. | E32: Protección contextual basada en riesgo.
A33: Bot Management | B33: Transaction Abuse Protection | C33: Protección de fraude automatizado. | D33: No aplica. | E33: Carding, gift-card abuse, inventory hoarding, scalping.
A34: Bot Management | B34: Mobile Bot Protection | C34: Protección de aplicaciones móviles. | D34: No aplica. | E34: SDK móvil y validación de integridad.
A35: Bot Management | B35: API Bot Protection | C35: Protección de APIs frente a bots. | D35: Reglas por endpoint. | E35: Correlación API + Bot Score + comportamiento.
B37: Capacidades complementarias recomendadas
B39: Capacidad | C39: Descripción propuesta
A40: Capacidades complementarias | B40: Context-Aware Rate Limiting | C40: Control granular de abuso basado en IP, sesión, token, clave API, usuario o contexto transaccional.
A41: Capacidades complementarias | B41: Content Delivery & Application Acceleration | C41: Optimización del rendimiento mediante distribución geográfica, caché y aceleración de aplicaciones.
A42: Capacidades complementarias | B42: DNS Security | C42: Protección y resiliencia DNS mediante DNSSEC, protección DDoS DNS y gestión segura de zonas.
A43: Capacidades complementarias | B43: TLS & Certificate Management | C43: Gestión centralizada de certificados, TLS moderno y autenticación mutua.
A44: Capacidades complementarias | B44: Application Traffic Management & Load Balancing | C44: Distribución inteligente de tráfico con health checks, failover y enrutamiento geográfico.
A45: Capacidades complementarias | B45: Threat Intelligence & Risk Scoring | C45: Uso de inteligencia de amenazas, reputación y modelos de riesgo para mejorar la detección y respuesta.
A46: Capacidades complementarias | B46: Security Observability & Integrations | C46: Dashboards, logs, SIEM/SOAR, APIs, exportación de eventos y correlación entre módulos.
A47: Capacidades complementarias | B47: Governance & Automation | C47: RBAC, auditoría, IaC, Terraform, APIs administrativas y flujos de aprobación.
...

Sheet Resumen SW
A1: 📌 Resumen SW — Totales por Empresa y Componente según Plazo (Años)
A3: Empresa | B3: Componente | C3: 3 años | D3: 5 años | G3: Total 3 años | H3: Total 5 años
A4: Mi Banco - Colombia | B4: SW | F4: Mi Banco - Colombia | G4: =+SUM(C4:C5) -> 0 | H4: =+SUM(D4:D5) -> 0
A5: Mi Banco - Colombia | B5: Soporte de Fábrica | F5: Tenpo - Chile | G5: =+SUM(C10:C11) -> 0 | H5: =+SUM(D10:D11) -> 0
B6: Servicio Implementacion
B7: Servicio Migracion
B8: Soporte Local - 3años
A10: Tenpo - Chile | B10: SW | F10: BCP - Perú | G10: =+SUM(C12:C13) -> 0 | H10: =+SUM(D12:D13) -> 0
A11: Tenpo - Chile | B11: Soporte de Fábrica | F11: YAPE | G11: =+SUM(C14:C15) -> 0 | H11: =+SUM(D14:D15) -> 0
A12: BCP - Perú | B12: SW | F12: Credicorp Capital Colombia/Credicorp Capital Chile/ASB - Panama/Credicorp Capital Perú/Credicorp Capital USA | G12: =+SUM(C16:C16) -> 0 | H12: =+SUM(D16:D16) -> 0 | I12: * La información de las empresas Credicorp Capital Colombia/Credicorp Capital Chile/ASB - Panama/Credicorp Capital Perú/Credicorp Capital USA se recibió el bloque.
A13: BCP - Perú | B13: Soporte de Fábrica | G13: =+SUM(#REF!) -> #REF! | H13: =+SUM(#REF!) -> #REF!
A14: YAPE | B14: SW | G14: =+SUM(#REF!) -> #REF! | H14: =+SUM(#REF!) -> #REF!
A15: YAPE | B15: Soporte de Fábrica | G15: =+SUM(#REF!) -> #REF! | H15: =+SUM(#REF!) -> #REF!
A16: Credicorp Capital Colombia/Credicorp Capital Chile/ASB - Panama/Credicorp Capital Perú/Credicorp Capital USA | B16: SW | G16: =+SUM(#REF!) -> #REF! | H16: =+SUM(#REF!) -> #REF!
A17: Mi Banco Perú | B17: SW | F17: Mi Banco Perú | G17: =+SUM(C17:C18) -> 0 | H17: =+SUM(D17:D18) -> 0
A18: Mi Banco Perú | B18: Soporte de Fábrica | F18: Pacifico-Prestadoras de Salud | G18: =+SUM(C19:C20) -> 0 | H18: =+SUM(D19:D20) -> 0
A19: Pacifico-Prestadoras de Salud | B19: SW | F19: Pacifico EPS | G19: =+SUM(C21:C22) -> 0 | H19: =+SUM(D21:D22) -> 0
A20: Pacifico-Prestadoras de Salud | B20: Soporte de Fábrica | F20: BCP - Bolivia | G20: =+SUM(C23:C24) -> 0 | H20: =+SUM(D23:D24) -> 0
A21: Pacifico EPS | B21: SW | F21: BCP Miami | G21: =+SUM(C25:C26) -> 0 | H21: =+SUM(D25:D26) -> 0
A22: Pacifico EPS | B22: Soporte de Fábrica | F22: Monokera | G22: =+SUM(C27:C28) -> 0 | H22: =+SUM(D27:D28) -> 0
A23: BCP - Bolivia | B23: SW | F23: Pacifico SI | G23: =+SUM(C29:C30) -> 0 | H23: =+SUM(D29:D30) -> 0
A24: BCP - Bolivia | B24: Soporte de Fábrica | F24: Prima AFP | G24: =+SUM(C31:C32) -> 0 | H24: =+SUM(D31:D32) -> 0
A25: BCP Miami | B25: SW | F25: Tyba | G25: =+SUM(C33:C34) -> 0 | H25: =+SUM(D33:D34) -> 0
A26: BCP Miami | B26: Soporte de Fábrica | F26: Culqui | G26: =+SUM(C35:C36) -> 0 | H26: =+SUM(D35:D36) -> 0
A27: Monokera | B27: SW | F27: IO | G27: =+SUM(C37:C38) -> 0 | H27: =+SUM(D37:D38) -> 0
A28: Monokera | B28: Soporte de Fábrica | F28: Total | G28: =SUM(G4:G27) -> #REF! | H28: =SUM(H4:H27) -> #REF!
A29: Pacifico SI | B29: SW
A30: Pacifico SI | B30: Soporte de Fábrica
A31: Prima AFP | B31: SW
A32: Prima AFP | B32: Soporte de Fábrica
A33: Tyba | B33: SW
A34: Tyba | B34: Soporte de Fábrica
A35: Culqui | B35: SW
A36: Culqui | B36: Soporte de Fábrica
A37: IO | B37: SW
A38: IO | B38: Soporte de Fábrica
A39: TOTAL
A50: * La información de las empresas Credicorp Capital Colombia/Credicorp Capital Chile/ASB - Panama/Credicorp Capital Perú/Credicorp Capital USA se recibió el bloque.

Sheet Resumen Labor
A1: 📌 Resumen Labor — Totales por Empresa según Tipo de Labor
A3: Empresa | B3: Implementación | C3: Soporte Local (3 años) | D3: Soporte Local (5 años) | E3: Capacitación | F3: Total General
A4: Mi Banco - Colombia
A5: Tenpo - Chile
A6: BCP - Perú
A7: YAPE
A8: Credicorp Capital Colombia/Credicorp Capital Chile/ASB - Panama/Credicorp Capital Perú/Credicorp Capital USA | G8: * La información de las empresas Credicorp Capital Colombia/Credicorp Capital Chile/ASB - Panama/Credicorp Capital Perú/Credicorp Capital USA se recibió el bloque.
A13: Mi Banco Perú
A14: Pacifico-Prestadoras de Salud
A15: Pacifico EPS
A16: BCP - Bolivia
A17: BCP Miami
A18: Monokera
A19: Pacifico SI
A20: Prima AFP
A21: Tyba
A22: Culqui
A23: IO
A24: TOTAL

Sheet homologacion cap. 
B2: Habilitacion Mandatoria | G2: Habilitacion Opcional | J2: No equivalente
B3: Web Application Firewall | C3: Bot Protection (ABP) | D3: Anti DDoS (Layer 7) | E3: Certificate Manager y mTLS | F3: Content Delivery Network (CDN) | G3: API Protection / API Security | H3: Client Side Protection (CSP) | I3: Account Take Over (ATO)
B4: cloud Application Protection - Complete | C4: cloud Application Protection - Complete | D4: Web DDos | E4: cloud Application Protection - Complete | F4: CDN | G4: API Security Plus | H4: cloud Application Protection - Complete | I4: cloud Application Protection - Complete

Sheet tarifario corporativo
A2: Tarifario - Crecimientos | D2: Precio por 1 año | E2: Precio por 3 años
